2018-04-21 14:43:45,479 ERROR: Exception on /api/v1/similar/ [GET] [in app.app.py:1560]
Traceback (most recent call last):
  File "/home/work/.local/share/virtualenvs/playlist_api-P1u_yyx0/lib/python3.6/site-packages/flask/app.py", line 1982, in wsgi_app
    response = self.full_dispatch_request()
  File "/home/work/.local/share/virtualenvs/playlist_api-P1u_yyx0/lib/python3.6/site-packages/flask/app.py", line 1614, in full_dispatch_request
    rv = self.handle_user_exception(e)
  File "/home/work/.local/share/virtualenvs/playlist_api-P1u_yyx0/lib/python3.6/site-packages/flask/app.py", line 1517, in handle_user_exception
    reraise(exc_type, exc_value, tb)
  File "/home/work/.local/share/virtualenvs/playlist_api-P1u_yyx0/lib/python3.6/site-packages/flask/_compat.py", line 33, in reraise
    raise value
  File "/home/work/.local/share/virtualenvs/playlist_api-P1u_yyx0/lib/python3.6/site-packages/flask/app.py", line 1612, in full_dispatch_request
    rv = self.dispatch_request()
  File "/home/work/.local/share/virtualenvs/playlist_api-P1u_yyx0/lib/python3.6/site-packages/flask/app.py", line 1598, in dispatch_request
    return self.view_functions[rule.endpoint](**req.view_args)
  File "/home/work/.local/share/virtualenvs/playlist_api-P1u_yyx0/lib/python3.6/site-packages/flask_limiter/extension.py", line 544, in __inner
    return obj(*a, **k)
  File "/home/work/Dropbox/eap/diplomatikh/source/playlist_api/api/routes.py", line 112, in get_k_similar
    ['santoniou.com@gmail.com'])
  File "/home/work/Dropbox/eap/diplomatikh/source/playlist_api/api/utils.py", line 17, in send_email
    mail.send(msg)
  File "/home/work/.local/share/virtualenvs/playlist_api-P1u_yyx0/lib/python3.6/site-packages/flask_mail.py", line 491, in send
    with self.connect() as connection:
  File "/home/work/.local/share/virtualenvs/playlist_api-P1u_yyx0/lib/python3.6/site-packages/flask_mail.py", line 144, in __enter__
    self.host = self.configure_host()
  File "/home/work/.local/share/virtualenvs/playlist_api-P1u_yyx0/lib/python3.6/site-packages/flask_mail.py", line 165, in configure_host
    host.login(self.mail.username, self.mail.password)
  File "/usr/lib/python3.6/smtplib.py", line 730, in login
    raise last_exception
  File "/usr/lib/python3.6/smtplib.py", line 721, in login
    initial_response_ok=initial_response_ok)
  File "/usr/lib/python3.6/smtplib.py", line 642, in auth
    raise SMTPAuthenticationError(code, resp)
smtplib.SMTPAuthenticationError: (535, b'5.7.8 Username and Password not accepted. Learn more at\n5.7.8  https://support.google.com/mail/?p=BadCredentials r57sm5172351edd.92 - gsmtp')
2018-04-21 14:46:28,643 INFO: Similar endpoint requested from ip 127.0.0.1 [in routes.routes.py:54]
2018-04-21 14:46:30,030 ERROR: Exception on /api/v1/similar/ [GET] [in app.app.py:1560]
Traceback (most recent call last):
  File "/home/work/.local/share/virtualenvs/playlist_api-P1u_yyx0/lib/python3.6/site-packages/flask/app.py", line 1982, in wsgi_app
    response = self.full_dispatch_request()
  File "/home/work/.local/share/virtualenvs/playlist_api-P1u_yyx0/lib/python3.6/site-packages/flask/app.py", line 1614, in full_dispatch_request
    rv = self.handle_user_exception(e)
  File "/home/work/.local/share/virtualenvs/playlist_api-P1u_yyx0/lib/python3.6/site-packages/flask/app.py", line 1517, in handle_user_exception
    reraise(exc_type, exc_value, tb)
  File "/home/work/.local/share/virtualenvs/playlist_api-P1u_yyx0/lib/python3.6/site-packages/flask/_compat.py", line 33, in reraise
    raise value
  File "/home/work/.local/share/virtualenvs/playlist_api-P1u_yyx0/lib/python3.6/site-packages/flask/app.py", line 1612, in full_dispatch_request
    rv = self.dispatch_request()
  File "/home/work/.local/share/virtualenvs/playlist_api-P1u_yyx0/lib/python3.6/site-packages/flask/app.py", line 1598, in dispatch_request
    return self.view_functions[rule.endpoint](**req.view_args)
  File "/home/work/.local/share/virtualenvs/playlist_api-P1u_yyx0/lib/python3.6/site-packages/flask_limiter/extension.py", line 544, in __inner
    return obj(*a, **k)
  File "/home/work/Dropbox/eap/diplomatikh/source/playlist_api/api/routes.py", line 112, in get_k_similar
    ['santoniou.com@gmail.com'])
  File "/home/work/Dropbox/eap/diplomatikh/source/playlist_api/api/utils.py", line 17, in send_email
    mail.send(msg)
  File "/home/work/.local/share/virtualenvs/playlist_api-P1u_yyx0/lib/python3.6/site-packages/flask_mail.py", line 491, in send
    with self.connect() as connection:
  File "/home/work/.local/share/virtualenvs/playlist_api-P1u_yyx0/lib/python3.6/site-packages/flask_mail.py", line 144, in __enter__
    self.host = self.configure_host()
  File "/home/work/.local/share/virtualenvs/playlist_api-P1u_yyx0/lib/python3.6/site-packages/flask_mail.py", line 165, in configure_host
    host.login(self.mail.username, self.mail.password)
  File "/usr/lib/python3.6/smtplib.py", line 730, in login
    raise last_exception
  File "/usr/lib/python3.6/smtplib.py", line 721, in login
    initial_response_ok=initial_response_ok)
  File "/usr/lib/python3.6/smtplib.py", line 642, in auth
    raise SMTPAuthenticationError(code, resp)
smtplib.SMTPAuthenticationError: (535, b'5.7.8 Username and Password not accepted. Learn more at\n5.7.8  https://support.google.com/mail/?p=BadCredentials z42sm5298348edz.36 - gsmtp')
2018-04-21 14:46:37,794 INFO: Similar endpoint requested from ip 127.0.0.1 [in routes.routes.py:54]
2018-04-21 14:46:39,737 ERROR: Exception on /api/v1/similar/ [GET] [in app.app.py:1560]
Traceback (most recent call last):
  File "/home/work/.local/share/virtualenvs/playlist_api-P1u_yyx0/lib/python3.6/site-packages/flask/app.py", line 1982, in wsgi_app
    response = self.full_dispatch_request()
  File "/home/work/.local/share/virtualenvs/playlist_api-P1u_yyx0/lib/python3.6/site-packages/flask/app.py", line 1614, in full_dispatch_request
    rv = self.handle_user_exception(e)
  File "/home/work/.local/share/virtualenvs/playlist_api-P1u_yyx0/lib/python3.6/site-packages/flask/app.py", line 1517, in handle_user_exception
    reraise(exc_type, exc_value, tb)
  File "/home/work/.local/share/virtualenvs/playlist_api-P1u_yyx0/lib/python3.6/site-packages/flask/_compat.py", line 33, in reraise
    raise value
  File "/home/work/.local/share/virtualenvs/playlist_api-P1u_yyx0/lib/python3.6/site-packages/flask/app.py", line 1612, in full_dispatch_request
    rv = self.dispatch_request()
  File "/home/work/.local/share/virtualenvs/playlist_api-P1u_yyx0/lib/python3.6/site-packages/flask/app.py", line 1598, in dispatch_request
    return self.view_functions[rule.endpoint](**req.view_args)
  File "/home/work/.local/share/virtualenvs/playlist_api-P1u_yyx0/lib/python3.6/site-packages/flask_limiter/extension.py", line 544, in __inner
    return obj(*a, **k)
  File "/home/work/Dropbox/eap/diplomatikh/source/playlist_api/api/routes.py", line 112, in get_k_similar
    ['santoniou.com@gmail.com'])
  File "/home/work/Dropbox/eap/diplomatikh/source/playlist_api/api/utils.py", line 17, in send_email
    mail.send(msg)
  File "/home/work/.local/share/virtualenvs/playlist_api-P1u_yyx0/lib/python3.6/site-packages/flask_mail.py", line 491, in send
    with self.connect() as connection:
  File "/home/work/.local/share/virtualenvs/playlist_api-P1u_yyx0/lib/python3.6/site-packages/flask_mail.py", line 144, in __enter__
    self.host = self.configure_host()
  File "/home/work/.local/share/virtualenvs/playlist_api-P1u_yyx0/lib/python3.6/site-packages/flask_mail.py", line 165, in configure_host
    host.login(self.mail.username, self.mail.password)
  File "/usr/lib/python3.6/smtplib.py", line 730, in login
    raise last_exception
  File "/usr/lib/python3.6/smtplib.py", line 721, in login
    initial_response_ok=initial_response_ok)
  File "/usr/lib/python3.6/smtplib.py", line 642, in auth
    raise SMTPAuthenticationError(code, resp)
smtplib.SMTPAuthenticationError: (535, b'5.7.8 Username and Password not accepted. Learn more at\n5.7.8  https://support.google.com/mail/?p=BadCredentials n8sm4970381edb.5 - gsmtp')
2018-04-21 14:48:18,227 INFO: Similar endpoint requested from ip 127.0.0.1 [in routes.routes.py:54]
